<?xml version="1.0"?>
<robot name="kuka_lwr" xmlns:xacro="http://www.ros.org/wiki/xacro">

	<!-- utils /-->
	<xacro:include filename="$(find kuka_robot)/robot/utils.xacro"/>
	<xacro:include filename="$(find kuka_robot)/robot/kuka_materials.xacro"
	/>

	<!-- gazebo and transmission models /-->
	<xacro:include filename="$(find kuka_robot)/robot/kuka_lwr.gazebo.xacro"/>
	<xacro:include filename="$(find kuka_robot)/robot/kuka_lwr.transmission.xacro"/>

	<!-- properties /-->
	<xacro:property name="base_mass" value="2.0"/>
	<xacro:property name="link_mass" value="2.0"/>
	<xacro:property name="velocity_scale" value="1"/>
	<xacro:property name="effort_scale" value="1"/>

	<!-- URDF model /-->
	<xacro:macro name="kuka_lwr" params="parent name *origin">

		<!-- First (shoulder) element of the arm. Fixed to its parent. -->
		<joint name="${parent}_${name}_base_joint" type="fixed">
			<insert_block name="origin"/>
			<origin xyz="0 0 0" rpy="0 0 0"/>
			<parent link="${parent}"/>
			<child link="${name}_base_link"/>
		</joint>

		<link name="${name}_base_link">
			<inertial>
				<mass value="${base_mass}"/>
				<origin xyz="0 0 0.055"  />
				<cylinder_inertia_def radius="0.06" length="0.11" mass="${base_mass}"/>
			</inertial>
			<visual>
				<origin xyz="0 0 0" rpy="0 0 ${M_PI}"/>
				<geometry>
					<mesh filename="package://kuka_robot/meshes/base.STL"/>
				</geometry>
				<material name="Kuka/Orange"/>
			</visual>
			<collision>
				<origin xyz="0 0 0.055" rpy="0 0 ${M_PI}"/>
				<geometry>
					<!-- <mesh filename="package://kuka_robot/meshes/convex/arm_base_convex.stl"/> -->
					<cylinder radius="0.07" length="0.11"/>
				</geometry>
			</collision>
		</link>

		<!-- Second segment of the arm. Joint along z-axis -->
		<joint name="${name}_0_joint" type="revolute">
			<origin xyz="0 0 0.11" rpy="0 0 0"/>
			<axis xyz="0 0 1"/>
			<limit lower="${-170 * M_PI / 180}" upper="${170 * M_PI / 180}" effort="1760" velocity="${velocity_scale * 110 * M_PI / 180}" />
			<dynamics friction="10.0" damping="1.0"/>
			<parent link="${name}_base_link"/>
			<child link="${name}_1_link"/>
		</joint>

		<link name="${name}_1_link">
			<inertial>
				<mass value="${link_mass}"/>
				<origin rpy="0 0 0" xyz="0 -0.06 0.130"/>
				<cuboid_inertia_def length="0.12" width="0.06" height="0.260" mass="${link_mass}"/>
			</inertial>
			<visual>
				<origin xyz="0 0 -0.008" rpy="0 0 ${M_PI}"/>
				<geometry>
					<mesh filename="package://kuka_robot/meshes/link_1.STL"/>
				</geometry>
				<material name="Kuka/Orange"/>
			</visual>
			<collision>
				<origin xyz="0 0 0.0" rpy="0 0 0"/>
				<geometry>
					<!--mesh filename="package://kuka_robot/meshes/convex/arm_segment_a_convex.stl"/-->
					<sphere radius="0.07"/>
				</geometry>
			</collision>
			<collision>
				<origin xyz="0 0.06 0.2" rpy="0 0 0"/>
				<geometry>
					<sphere radius="0.07"/>
				</geometry>
			</collision>
			<collision>
				<origin xyz="0 0.03 0.1" rpy="-0.291 0 0"/>
				<geometry>
					<cylinder radius="0.07" length="0.208"/>
				</geometry>
			</collision>
		</link>

		<!-- Third segment of the arm. Joint along y-axis -->
		<joint name="${name}_1_joint" type="revolute">
			<origin xyz="0 0 0.2005" rpy="0 0 0"/>
			<axis xyz="0 -1 0"/>
			<limit lower="${-120 * M_PI / 180}" upper="${120 * M_PI / 180}" effort="1760" velocity="${velocity_scale * 110 * M_PI / 180}" />
			<dynamics friction="10.0" damping="1.0"/>
			<parent link="${name}_1_link"/>
			<child link="${name}_2_link"/>
		</joint>

		<link name="${name}_2_link">
			<inertial>
				<mass value="${link_mass}"/>
				<origin rpy="0 0 0" xyz="0 0.06 ${0.130 - 0.06}"/>
				<cuboid_inertia_def length="0.12" width="0.06" height="0.260" mass="${link_mass}"/>
			</inertial>

			<visual>
				<origin xyz="0 0 0.0" rpy="0 0 ${M_PI}"/>
				<geometry>
					<mesh filename="package://kuka_robot/meshes/link_2.STL"/>
				</geometry>
				<material name="Kuka/Orange"/>
			</visual>
			<collision>
				<origin xyz="0 0 0.2" rpy="0 0 0"/>
				<geometry>
					<!--mesh filename="package://kuka_robot/meshes/convex/arm_segment_b_convex.stl"/-->
					<sphere radius="0.07"/>
				</geometry>
			</collision>
			<collision>
				<origin xyz="0 -0.06 0.0" rpy="0 0 0"/>
				<geometry>
					<sphere radius="0.07"/>
				</geometry>
			</collision>
			<collision>
				<origin xyz="0 -0.03 0.1" rpy="-0.291 0 0"/>
				<geometry>
					<cylinder radius="0.07" length="0.208"/>
				</geometry>
			</collision>
		</link>

		<!-- Fourth element of the arm. z-axis -->
		<joint name="${name}_2_joint" type="revolute">
			<origin xyz="0 0 0.20" rpy="0 0 0"/>
			<axis xyz="0 0 1"/>
			<limit lower="${-170 * M_PI / 180}" upper="${170 * M_PI / 180}" effort="1000" velocity="${velocity_scale * 128 * M_PI / 180}" />
			<dynamics friction="10.0" damping="1.0"/>
			<parent link="${name}_2_link"/>
			<child link="${name}_3_link"/>
		</joint>

		<link name="${name}_3_link">
			<inertial>
				<mass value="${link_mass}"/>
				<origin rpy="0 0 0" xyz="0 0.06 0.130"/>
				<cuboid_inertia_def length="0.12" width="0.06" height="0.260" mass="${link_mass}"/>
			</inertial>

			<visual>
				<origin xyz="0 0 -0.008" rpy="0 0 ${M_PI}"/>
				<geometry>
					<mesh filename="package://kuka_robot/meshes/link_3.STL"/>
				</geometry>
				<material name="Kuka/Orange"/>
			</visual>
			<collision>
				<origin xyz="0 0 0.0" rpy="0 0 0"/>
				<geometry>
					<sphere radius="0.07"/>
				</geometry>
			</collision>
			<collision>
				<origin xyz="0 -0.06 0.2" rpy="0 0 0"/>
				<geometry>
					<sphere radius="0.07"/>
				</geometry>
			</collision>
			<collision>
				<origin xyz="0 -0.03 0.1" rpy="0.291 0 0"/>
				<geometry>
					<cylinder radius="0.07" length="0.208"/>
				</geometry>
			</collision>
		</link> 

		<!-- fifth element of the arm. x-axis -->
		<joint name="${name}_3_joint" type="revolute">
			<origin xyz="0 0 0.20" rpy="0 0 0"/>
			<axis xyz="0 1 0"/>
			<limit lower="${-120 * M_PI / 180}" upper="${120 * M_PI / 180}" effort="1000" velocity="${velocity_scale * 128 * M_PI / 180}" />
			<dynamics friction="10.0" damping="1.0"/>
			<parent link="${name}_3_link"/>
			<child link="${name}_4_link"/>
		</joint>

		<link name="${name}_4_link">
			<inertial>
				<mass value="${link_mass}"/>
				<origin rpy="0 0 0" xyz="0 -0.06 ${0.130 - 0.06}"/>
				<cuboid_inertia_def length="0.12" width="0.06" height="0.2600" mass="${link_mass}"/>
			</inertial>

			<visual>
				<origin xyz="0 0 0.0" rpy="0 0 ${M_PI}"/>
				<geometry>
					<mesh filename="package://kuka_robot/meshes/link_4.STL"/>
				</geometry>
				<material name="Kuka/Orange"/>
			</visual>
			<collision>
			<origin xyz="0 0 0.2" rpy="0 0 0"/>
			<geometry>
				<sphere radius="0.07"/>
			</geometry>
			</collision>
			<collision>
				<origin xyz="0 0.06 0.0" rpy="0 0 0"/>
				<geometry>
					<sphere radius="0.07"/>
				</geometry>
			</collision>
			<collision>
				<origin xyz="0 0.03 0.1" rpy="0.291 0 0"/>
				<geometry>
					<cylinder radius="0.07" length="0.208"/>
				</geometry>
			</collision>
		</link> 

		<!-- Sixth element of the arm. z-axis -->
		<joint name="${name}_4_joint" type="revolute">
			<origin xyz="0 0 0.20" rpy="0 0 0"/>
			<axis xyz="0 0 1"/>
			<limit lower="${-170 * M_PI / 180}" upper="${170 * M_PI / 180}" effort="1000" velocity="${velocity_scale * 204 * M_PI / 180}" />
			<dynamics friction="10.0" damping="1.0"/>
			<parent link="${name}_4_link"/>
			<child link="${name}_5_link"/>
		</joint>

		<link name="${name}_5_link">
			<inertial>
				<mass value="${link_mass}"/>
				<origin rpy="0 0 0" xyz="0 0 0.124"/>
				<cuboid_inertia_def length="0.12" width="0.06" height="0.248" mass="${link_mass}"/>
			</inertial>

			<visual>
				<origin xyz="0 0 -0.008" rpy="0 0 ${M_PI}"/>
				<geometry name="${name}_5_geom">
					<mesh filename="package://kuka_robot/meshes/link_5.STL"/>
				</geometry>
				<material name="Kuka/Orange"/>
			</visual>

			<collision>
				<origin xyz="0 0 0.0" rpy="0 0 0"/>
				<geometry>
					<sphere radius="0.07"/>
				</geometry>
			</collision>
			<collision>
				<origin xyz="0 0.04 0.19" rpy="0 0 0"/>
				<geometry>
					<sphere radius="0.07"/>
				</geometry>
			</collision>
			<collision>
				<origin xyz="0 0.02 0.095" rpy="-0.207 0 0"/>
				<geometry>
					<cylinder radius="0.07" length="0.198"/>
				</geometry>
			</collision>
		</link>

		<!-- Seventh element of the arm. z-axis -->
		<joint name="${name}_5_joint" type="revolute">
			<origin xyz="0 0 0.19" rpy="0 0 0"/>
			<axis xyz="0 -1 0"/>
			<limit lower="${-120 * M_PI / 180}" upper="${120 * M_PI / 180}" effort="380" velocity="${velocity_scale * 184 * M_PI / 180}" />
			<dynamics friction="10.0" damping="1.0"/>
			<parent link="${name}_5_link"/>
			<child link="${name}_6_link"/>
		</joint>

		<link name="${name}_6_link">
			<inertial>
				<mass value="0.2"/>
				<origin rpy="0 0 0" xyz="0 0 0.0625"/>
				<cuboid_inertia_def length="0.125" width="0.125" height="0.125" mass="0.2"/>
			</inertial>

			<visual>
				<origin xyz="0 0 0" rpy="0 0 ${M_PI}"/>
				<geometry>
					<mesh filename="package://kuka_robot/meshes/link_6.STL"/>
				</geometry>
			<material name="Kuka/Grey"/>
			</visual>
			<collision>
			<origin xyz="0 0 0" rpy="0 0 ${M_PI}"/>
			<geometry>
				<mesh filename="package://kuka_robot/meshes/convex/arm_wrist_convex.stl"/>
			</geometry>
			</collision>
		</link>

		<!-- Eighth element of the arm. z-axis -->
		<joint name="${name}_6_joint" type="revolute">
			<origin xyz="0 0 0.078" rpy="0 0 0"/>
			<axis xyz="0 0 1"/>
			<limit lower="${-170 * M_PI / 180}" upper="${170 * M_PI / 180}" effort="380" velocity="${velocity_scale * 184 * M_PI / 180}" />
			<dynamics friction="10.0" damping="1.0"/>
			<parent link="${name}_6_link"/>
			<child link="${name}_7_link"/>
		</joint>

		<link name="${name}_7_link">
			<inertial>
				<mass value="0.2"/>
				<origin xyz="0 0 0"/>
				<cuboid_inertia_def length="1" width="1" height="1" mass="0.2"/>
			</inertial>
			<visual>
				<origin xyz="0 0 0" rpy="0 0 ${M_PI}"/>
				<geometry>
					<mesh filename="package://kuka_robot/meshes/link_7.STL"/>
				</geometry>
			<material name="Kuka/DarkGrey"/>
			</visual>

			<collision>
			<origin xyz="0 0 0" rpy="0 0 ${M_PI}"/>
			<geometry>
				<cylinder radius="0.04" length="0.05"/>
			</geometry>
			</collision>
		</link>

               <!-- Wrist of gripper. fixed to link 6 -->
        	<joint name="${name}_gripper_wrist_fix" type="fixed">
			<origin xyz="0 0 0" rpy="0 0 0" />
			<axis xyz="0 0 1"/>
			<parent link="${name}_7_link"/>
			<child link="${name}_gripper_wrist"/>
		</joint>

		<link name="${name}_gripper_wrist">
			<inertial>
			      <origin
				xyz="0.0303673809619356 4.00707611352118E-10 0.000140374211043737"
				rpy="0 0 0" />
			      <mass
				value="0.717337417215465" />
			      <inertia
				ixx="0.000437528795624211"
				ixy="2.79334685089828E-12"
				ixz="3.9184388902034E-06"
				iyy="0.000211170064630335"
				iyz="-4.20757370549832E-12"
				izz="0.000486392340366095" />
			    </inertial>
			<visual>
				<origin xyz="0 0 0" rpy="0 0 ${M_PI}"/>
				<geometry>
					<mesh filename="package://kuka_robot/meshes/gripper_wrist_link.stl"/>
				</geometry>
			<material name="Kuka/DarkGrey"/>
			</visual>

			<collision>
				<origin xyz="0 0 0" rpy="0 0 ${M_PI}"/>
				<geometry>
					<mesh filename="package://kuka_robot/meshes/gripper_wrist_link.stl"/>
				</geometry>
			</collision>
		</link> 

		<!-- Left finger.  -->
		<joint name="${name}_left_finger_joint" type="revolute">
		    <origin xyz="0 0.0209999999999993 0.042" rpy="0 0 0" />
		    <parent link="${name}_gripper_wrist" />
		    <child link="${name}_left_finger_link" />
		    <axis
		      xyz="-1 0 0" />
		    <limit
		      lower="-0.2"
		      upper="1"
		      effort="100"
		      velocity="1" />
		  </joint>

		<link name="${name}_left_finger_link">
		    <inertial>
		      <origin
			xyz="3.72403910764429E-08 0.0148725895621533 0.0333609018907974"
			rpy="0 0 0" />
		      <mass
			value="0.111981711598486" />
		      <inertia
			ixx="0.00486392340366094"
			ixy="4.20757000035677E-12"
			ixz="-3.91843889020299E-06"
			iyy="0.00211170064630335"
			iyz="2.79335159568522E-12"
			izz="0.00437528795624211" />
		    </inertial>
		    <visual>
		      <origin
			xyz="0 0 0"
			rpy="0 0 0" />
		      <geometry>
			<mesh
			  filename="package://kuka_robot/meshes/left_finger_link.stl" />
		      </geometry>
		      <material
			name="">
			<color
			  rgba="0.4 0.4 0.4 1" />
		      </material>
		    </visual>
		    <collision>
		      <origin
			xyz="0 0.015 0.1"
			rpy="0 1.570796 0" />
		      <geometry>
		        <cylinder length="0.1" radius="0.01" />
		      </geometry>
		    </collision>
		    <collision>
		      <origin
			xyz="0 0.015 0.06"
			rpy="0 1.570796 0" />
		      <geometry>
		        <cylinder length="0.1" radius="0.01" />
		      </geometry>
		    </collision>
		  </link>

		<!-- right finger.  -->
		<joint name="${name}_right_finger_joint" type="revolute">
		    <origin xyz="0 -0.0209999999999993 0.042" rpy="0 0 0" />
		    <parent link="${name}_gripper_wrist" />
		    <child link="${name}_right_finger_link" />
		    <axis
		      xyz="-1 0 0" />
		    <limit
		      lower="-1"
		      upper="0.2"
		      effort="100"
		      velocity="1" />
		  </joint>

		<link name="${name}_right_finger_link">
		    <inertial>
		      <origin
			xyz="3.72403910764429E-08 -0.0148725895621533 0.0333609018907974"
			rpy="0 0 0" />
		      <mass
			value="0.111981711598486" />
		      <inertia
			ixx="0.00486392340366094"
			ixy="4.20757000035677E-12"
			ixz="-3.91843889020299E-06"
			iyy="0.00211170064630335"
			iyz="2.79335159568522E-12"
			izz="0.00437528795624211" />
		    </inertial>
		    <visual>
		      <origin
			xyz="0 0 0"
			rpy="0 0 0" />
		      <geometry>
			<mesh
			  filename="package://kuka_robot/meshes/right_finger_link.stl" />
		      </geometry>
		      <material
			name="">
			<color
			  rgba="0.4 0.4 0.4 1" />
		      </material>
		    </visual>
		    <collision>
		      <origin
			xyz="0 -0.015 0.1"
			rpy="0 1.570796 0" />
		      <geometry>
		        <cylinder length="0.1" radius="0.01" />
		      </geometry>
		    </collision>
		    <collision>
		      <origin
			xyz="0 -0.015 0.06"
			rpy="0 1.570796 0" />
		      <geometry>
		        <cylinder length="0.1" radius="0.01" />
		      </geometry>
		    </collision>

		  </link> 

		<xacro:kuka_lwr_gazebo name="${name}"/>
		<xacro:kuka_lwr_transmission name="${name}"/> 

	</xacro:macro>

</robot>
